<?xml version="1.0" ?>
<!-- =================================================================================== -->
<!-- |    This document was autogenerated by xacro from robot.xacro                    | -->
<!-- |    EDITING THIS FILE BY HAND IS NOT RECOMMENDED                                 | -->
<!-- =================================================================================== -->
<robot name="a1_description" xmlns:xacro="http://www.ros.org/wiki/xacro">
  <material name="black">
    <color rgba="0.0 0.0 0.0 1.0"/>
  </material>
  <material name="grey">
    <color rgba="0.2 0.2 0.2 1.0"/>
  </material>
  <material name="silver">
    <color rgba="0.913725490196 0.913725490196 0.847058823529 1.0"/>
  </material>
  <material name="white">
    <color rgba="1.0 1.0 1.0 1.0"/>
  </material>




  <link name="base">
    <visual>
      <origin rpy="0 0 0" xyz="0 0 0"/>
      <geometry>
        <box size="0.001 0.001 0.001"/>
      </geometry>
    </visual>
    <!-- added so pybullet doesn't complain and set mass 1 diagintertia 1-->
    <inertial>
      <origin rpy="0 0 0" xyz="0 0 0"/>
      <mass value="0.00001"/>
      <inertia ixx="1e-5" ixy="0" ixz="0" iyy="1e-5" iyz="0" izz="1e-5"/>
    </inertial>
  </link>

  <joint name="floating_base" type="fixed">
    <origin rpy="0 0 0" xyz="0 0 0"/>
    <parent link="base"/>
    <child link="trunk"/>
  </joint>
  <link name="trunk">
    <visual>
      <origin rpy="0 -1.57 0" xyz="0 0 0"/>
      <geometry>
        <box size="0.05 0.05 0.05"/>
      </geometry>
      <material name="orange"/>
    </visual>
    <collision>
      <origin rpy="0 -1.57 0" xyz="0 0 0"/>
      <geometry>
        <box size="0.05 0.05 0.05"/>
      </geometry>
    </collision>
    <inertial>
      <origin rpy="0 0 0" xyz="0.012731 0.002186 0.000515"/>
      <mass value="1"/>
      <inertia ixx="0.01683993" ixy="8.3902e-05" ixz="0.000597679" iyy="0.056579028" iyz="2.5134e-05" izz="0.064713601"/>
    </inertial>
  </link>
  <joint name="imu_joint" type="fixed">
    <parent link="trunk"/>
    <child link="imu_link"/>
    <origin rpy="0 0 0" xyz="0 0 0"/>
  </joint>
  <link name="imu_link">
    <inertial>
      <mass value="0.001"/>
      <origin rpy="0 0 0" xyz="0 0 0"/>
      <inertia ixx="0.0001" ixy="0" ixz="0" iyy="0.0001" iyz="0" izz="0.0001"/>
    </inertial>
    <visual>
      <origin rpy="0 0 0" xyz="0 0 0"/>
      <geometry>
        <box size="0.001 0.001 0.001"/>
      </geometry>
      <material name="red"/>
    </visual>
    <collision>
      <origin rpy="0 0 0" xyz="0 0 0"/>
      <geometry>
        <box size=".001 .001 .001"/>
      </geometry>
    </collision>
  </link>

<joint name="hip_joint" type="fixed">
    <!-- <origin rpy="0 0 0" xyz="0.196 -0.049664 0"/> -->
    <origin rpy="0 0 0" xyz="0 0 0"/>
    <parent link="trunk"/>
    <child link="hip"/>
    <axis xyz="1 0 0"/>
    <dynamics damping="0.0" friction="0.0"/>
    <limit effort="18" lower="-1.0471975512" upper="0.872664625997" velocity="40"/>
  </joint>
  <link name="hip">
    <visual>
      <origin rpy="0 3.14159265359 0" xyz="0 0 0"/>
      <!-- <origin rpy="3.14159265359 0 0" xyz="0 0 0"/> -->
      <geometry>
        <mesh filename="meshes/hip.STL" scale="1 1 1"/>
      </geometry>
      <material name="orange"/>
    </visual>
    <collision>
      <origin rpy="0 3.14159265359 0" xyz="0 0 0"/>
      <!-- <origin rpy="3.14159265359 0 0" xyz="0 0 0"/> -->
      <geometry>
        <!-- <cylinder length="0.04" radius="0.046"/> -->
        <mesh filename="meshes/hip.STL" scale="1 1 1"/>
      </geometry>
    </collision>
    <inertial>
      <origin rpy="0 0 0" xyz="-0.0 0.036 0.0"/>
      <mass value="0.57"/>
      <inertia ixx="0.000381" ixy="-5.8e-05" ixz="-4.5e-07" iyy="0.00056" iyz="9.5e-07" izz="0.000444"/>
    </inertial>
  </link>
  <!-- FR thigh -->
  <joint name="thigh_joint" type="revolute">
    <!-- <origin rpy="0 0 0" xyz="0 -0.077476 0"/> -->
    <origin rpy="0 0 0" xyz="0 0 0"/>
    <parent link="hip"/>
    <child link="thigh"/>
    <axis xyz="0 1 0"/>
    <dynamics damping="0.0" friction="0.0"/>
    <limit effort="18" lower="-3.14" upper="3.14" velocity="40"/>
  </joint>
  <link name="thigh">
    <visual>
      <origin rpy="0 0 0" xyz="0 0 0"/>
      <geometry>
        <mesh filename="meshes/thigh.STL" scale="1 1 1"/>
      </geometry>
      <material name="orange"/>
    </visual>
    <collision>
      <origin rpy="0 0 0" xyz="0 0 0"/>
      <!-- <origin rpy="0 1.57079632679 0" xyz="0 0 0"/> -->
      <geometry>
        <!-- <box size="0.2 0.0245 0.034"/> -->
        <mesh filename="meshes/thigh.STL" scale="1 1 1"/>
      </geometry>
    </collision>
    <inertial>
      <origin rpy="0 0 0" xyz="0.0 0.016 -0.02"/>
      <mass value="0.634"/>
      <inertia ixx="0.001983" ixy="0.000245" ixz="1.3e-05" iyy="0.002103" iyz="1.5e-06" izz="0.000408"/>
    </inertial>
  </link>
  <!-- FR calf -->
  <joint name="calf_joint" type="revolute">
    <origin rpy="0 0 0" xyz="0 0.0106 -0.2115"/>
    <parent link="thigh"/>
    <child link="calf"/>
    <axis xyz="0 1 0"/>
    <dynamics damping="0.01" friction="0.2"/>
    <limit effort="18" lower="-3.14159265359" upper="3.14159265359" velocity="40"/>
  </joint>
  <link name="calf">
    <visual>
      <origin rpy="0 0 0" xyz="0 0 0"/>
      <geometry>
        <mesh filename="meshes/calf.STL" scale="1 1 1"/>
      </geometry>
      <material name="orange"/>
    </visual>
    <collision>
      <origin rpy="0 0 0" xyz="0 0 0"/>
       <!-- <origin rpy="0 1.57079632679 0" xyz="0 0 0"/> -->
      <geometry>
        <!-- <box size="0.2 0.016 0.016"/> -->
        <mesh filename="meshes/calf.STL" scale="1 1 1"/>
      </geometry>
    </collision>
    <inertial>
      <origin rpy="0 0 0" xyz="0 0 -0.209"/>
      <mass value="0.064"/>
      <inertia ixx="0.000245" ixy="0.0" ixz="0.0" iyy="0.000248" iyz="0.0" izz="6e-06"/>
    </inertial>
  </link>
  <!-- FR foot -->
  <joint name="foot_fixed" type="fixed">
    <origin rpy="0 0 0" xyz="0 0.0096 -0.21039"/>
    <parent link="calf"/>
    <child link="foot"/>
  </joint>
  <link name="foot">
    <visual>
      <origin rpy="0 0 0" xyz="0 0 0"/>
      <geometry>
        <!-- <sphere radius="0.01"/> -->
        <mesh filename="meshes/foot.STL" scale="1 1 1"/>
      </geometry>
      <material name="orange"/>
    </visual>
    <collision>
      <origin rpy="0 0 0" xyz="0 0 0"/>
      <geometry>
        <!-- <sphere radius="0.02"/> -->
        <mesh filename="meshes/foot.STL" scale="1 1 1"/>
      </geometry>
    </collision>
    <inertial>
      <!-- <origin rpy="0 0 0" xyz="0.0 0.0 0"/> -->
      <mass value="0.15"/>
      <inertia ixx="2.5e-05" ixy="0.0" ixz="0.0" iyy="2.5e-05" iyz="0.0" izz="2.5e-05"/>
    </inertial>
  </link>

  <link name="world">
  <inertial>
      <mass value="0"/>
      <inertia ixx="0.2125" ixy="-0.005" ixz="0.0225" iyy="0.205" iyz="0.045" izz="0.0125"/>
      <origin rpy="0 0 0" xyz="0 0 0"/>
    </inertial>
  </link>

  <link name="x_prismatic">
   <inertial>
      <mass value="0.01"/>
      <inertia ixx="0.2125" ixy="-0.005" ixz="0.0225" iyy="0.205" iyz="0.045" izz="0.0125"/>
      <origin rpy="0 0 0" xyz="0 0 0"/>
    </inertial>
  </link>
  
  <joint name="x_to_world" type="prismatic">
    <parent link="world"/>
    <child link="x_prismatic"/>
    <axis xyz="1 0 0"/>
    <limit effort="0.0" lower="1" upper="-1" velocity="1000.0"/>
    <origin rpy="0 0 0" xyz="0 0 0"/>
  </joint>
    
  <joint name="z_to_x" type="prismatic">
    <parent link="x_prismatic"/>
    <child link="base"/> 
    <axis xyz="0 0 1"/>
     <limit effort="0.0" lower="1" upper="-1" velocity="1000.0"/>
    <origin rpy="0 0 0" xyz="0 0 0"/>
  </joint> 

<!--   <joint name="z_to_x" type="prismatic">
    <parent link="x_prismatic"/>
    <child link="z_prismatic"/> 
    <axis xyz="0 0 1"/>
     <limit effort="0.0" lower="1" upper="-1" velocity="1000.0"/>
    <origin rpy="0 0 0" xyz="0 0 0"/>
  </joint> 
    
  <link name="z_prismatic">
   <inertial>
      <mass value="0.01"/>
      <inertia ixx="0.2125" ixy="-0.005" ixz="0.0225" iyy="0.205" iyz="0.045" izz="0.0125"/>
      <origin rpy="0 0 0" xyz="0 0 0"/>
    </inertial>
  </link>
  
  <joint name="torso_to_z" type="continuous">
    <parent link="z_prismatic"/>
    <child link="base"/>
    <axis xyz="0 1 0"/>
    <origin rpy="0 0 0" xyz="0 0 0"/>
  </joint> -->

</robot>